Workbook

Sheet DON CHACHO
A1: CARNE
A2: GRANJA DON CHACHO | F2: INCREMENTO | G2: 1.05 | J2: RINDE CARNE GRANJA DON CHACHO
A3: CORTES: | B3: penultimo | C3: ultimo | D3: $ Actual | E3: Pegar $ Actual para calcular incremento | F3: Valor con calculo de incremento | J3: MEDIA FORRES | K3: KGR | N3: PRECIO | O3: TOTALES
A4: VACIO | B4: 21890 | C4: 22990 | D4: 22990 | E4: 21890 | F4: =PRODUCT(E4,G2) -> 22984.5 | J4: MEDIA RES 111 | K4: 111 | L4: -1 | N4: 10400 | O4: =PRODUCT(K4:N4) -> -1154400
A5: QUEPERI | B5: 21790 | C5: 22950 | D5: 22950 | E5: 21790 | F5: =PRODUCT(E5,G2) -> 22879.5 | J5: SIN PELAR HUESO | O5: =PRODUCT(K5:N5) -> 0
A6: MATAMBRE | B6: 18750 | C6: 19690 | D6: 18690 | E6: 18750 | F6: =PRODUCT(E6,G2) -> 19687.5 | J6: Asado: | O6: =PRODUCT(K6:N6) -> 0
A7: VUELITO | B7: 25400 | C7: 26670 | D7: 25950 | E7: 25400 | F7: =PRODUCT(E7,G2) -> 26670 | J7: Vacio | K7: 3.335 | N7: =(D4) -> 22990 | O7: =PRODUCT(K7:N7) -> 76671.65
A8: COSTILLA ESPECIAL | B8: 18900 | C8: 19850 | D8: 19500 | E8: 18900 | F8: =PRODUCT(E8,G2) -> 19845 | J8: Queperi | K8: 2.58 | N8: =(D5) -> 22950 | O8: =PRODUCT(K8:N8) -> 59211
A9: TAPA DE NALGA | B9: 18650 | C9: 19580 | D9: 19180 | E9: 18650 | F9: =PRODUCT(E9,G2) -> 19582.5 | J9: Matambre | K9: 1.395 | N9: =(D6) -> 18690 | O9: =PRODUCT(K9:N9) -> 26072.55
A10: TAPA DE ASADO | B10: 16750 | C10: 17590 | D10: 17590 | E10: 16750 | F10: =PRODUCT(E10,G2) -> 17587.5 | J10: Vuelito | K10: 0.48 | N10: =(D7) -> 25950 | O10: =PRODUCT(K10:N10) -> 12456
A11: FALDA DE ESPALDA | B11: 15350 | C11: 16100 | D11: 15900 | E11: 15350 | F11: =PRODUCT(E11,G2) -> 16117.5 | J11: Costilla | K11: 8.85 | N11: =(D8) -> 19500 | O11: =PRODUCT(K11:N11) -> 172575
A12: CORTE AMERICANO | B12: 19300 | C12: 20270 | D12: 19900 | E12: 19300 | F12: =PRODUCT(E12,G2) -> 20265 | J12: Tapa de Nalga | K12: 1.31 | N12: =(D9) -> 19180 | O12: =PRODUCT(K12:N12) -> 25125.8
A13: COSTELETA | B13: 17850 | C13: 18800 | D13: 17900 | E13: 17850 | F13: =PRODUCT(E13,G2) -> 18742.5 | J13: Tapa de Asado | K13: 2.095 | N13: =(D10) -> 17590 | O13: =PRODUCT(K13:N13) -> 36851.05
A14: FILET | B14: 23650 | C14: 24830 | D14: 23830 | E14: 23650 | F14: =PRODUCT(E14,G2) -> 24832.5 | J14: ( oferta asado 4kg.) | K14: 11.61 | N14: =(D42/4) -> 11400 | O14: =PRODUCT(K14:N14) -> 132354
A15: LOMO | B15: 24050 | C15: 25250 | D15: 24850 | E15: 24050 | F15: =PRODUCT(E15,G2) -> 25252.5 | J15: Blandos Especiales: | O15: =PRODUCT(K15:N15) -> 0
A16: PULPA | B16: 24050 | C16: 25250 | D16: 24850 | E16: 24050 | F16: =PRODUCT(E16,G2) -> 25252.5 | J16: Filet | K16: 1.855 | N16: =(D14) -> 23830 | O16: =PRODUCT(K16:N16) -> 44204.65
A17: PICANA | B17: 20600 | C17: 21650 | D17: 20850 | E17: 20600 | F17: =PRODUCT(E17,G2) -> 21630 | J17: Lomo | K17: 5.895 | N17: =(D15) -> 24850 | O17: =PRODUCT(K17:N17) -> 146490.75
A18: PECETO | B18: 21800 | C18: 22890 | D18: 22190 | E18: 21800 | F18: =PRODUCT(E18,G2) -> 22890 | J18: Pulpa | K18: 4.22 | N18: =(D16) -> 24850 | O18: =PRODUCT(K18:N18) -> 104867
A19: BOLA DE LOMO | B19: 18750 | C19: 19750 | D19: 19750 | E19: 18750 | F19: =PRODUCT(E19,G2) -> 19687.5 | J19: Picana | K19: 4.7 | N19: =(D17) -> 20850 | O19: =PRODUCT(K19:N19) -> 97995
A20: CUADRADA | B20: 18750 | C20: 19750 | D20: 19750 | E20: 18750 | F20: =PRODUCT(E20,G2) -> 19687.5 | J20: Peceto | K20: 1.64 | N20: =(D18) -> 22190 | O20: =PRODUCT(K20:N20) -> 36391.6
A21: PALETA | B21: 17590 | C21: 18470 | D21: 18950 | E21: 17590 | F21: =PRODUCT(E21,G2) -> 18469.5 | J21: Bola de Lomo | K21: 4.15 | N21: =(D19) -> 19750 | O21: =PRODUCT(K21:N21) -> 81962.5
A22: SOBACO | B22: 14650 | C22: 15380 | D22: 15380 | E22: 14650 | F22: =PRODUCT(E22,G2) -> 15382.5 | J22: Cuadrada | K22: 3.315 | N22: =(D20) -> 19750 | O22: =PRODUCT(K22:N22) -> 65471.25
A23: TORTUGA | B23: 14650 | C23: 15380 | D23: 15380 | E23: 14650 | F23: =PRODUCT(E23,G2) -> 15382.5 | J23: Paleta | K23: 3.135 | N23: =(D21) -> 18950 | O23: =PRODUCT(K23:N23) -> 59408.25
A24: MOLIDA COMUN | B24: 12050 | C24: 12650 | D24: 11950 | E24: 12050 | F24: =PRODUCT(E24,G2) -> 12652.5 | J24: Blandos Comunes: | O24: =PRODUCT(K24:N24) -> 0
A25: PUCHERO ESPECIAL | B25: 9800 | C25: 10290 | D25: 10400 | E25: 9800 | F25: =PRODUCT(E25,G2) -> 10290 | J25: Sobaco | K25: 3.77 | N25: =(D22) -> 15380 | O25: =PRODUCT(K25:N25) -> 57982.6
A26: PUCHERO PALETA | B26: 9800 | C26: 10290 | D26: 10400 | E26: 9800 | F26: =PRODUCT(E26,G2) -> 10290 | J26: Tortuga | K26: 1.48 | N26: =(D23) -> 15380 | O26: =PRODUCT(K26:N26) -> 22762.4
A27: PUCHERO COGOTE | B27: 9500 | C27: 9975 | D27: 9975 | E27: 9500 | F27: =PRODUCT(E27,G2) -> 9975 | J27: Blando Comun | O27: =PRODUCT(K27:N27) -> 0
A28: PUCHERO COMUN | B28: 2400 | C28: 2500 | D28: 3000 | E28: 2400 | F28: =PRODUCT(E28,G2) -> 2520 | J28: Pucheros Especiales: | O28: =PRODUCT(K28:N28) -> 0
A29: PUCHERO COMUN 3KG | B29: 4300 | C29: 4500 | D29: 7500 | E29: 4300 | F29: =PRODUCT(E29,G2) -> 4515 | J29: Osobuco | K29: 3.545 | N29: =(D25) -> 10400 | O29: =PRODUCT(K29:N29) -> 36868
A30: BUTIFARRA | B30: 11900 | C30: 12490 | D30: 12490 | E30: 11900 | F30: =PRODUCT(E30,G2) -> 12495 | J30: Puchero Comun oferta | K30: 12.44 | N30: =(D29/3) -> 2500 | O30: =PRODUCT(K30:N30) -> 31100
A31: CHORIZO CRIOLLO | B31: 11100 | C31: 11650 | D31: 11850 | E31: 11100 | F31: =PRODUCT(E31,G2) -> 11655 | J31: Grasa parque | K31: 9.395 | N31: 1 | O31: =PRODUCT(K31:N31) -> 9.395
A32: CHORIZO DE CERDO | B32: 11300 | C32: 11850 | D32: 11950 | E32: 11300 | F32: =PRODUCT(E32,G2) -> 11865 | J32: Huesos y Desperdicios | K32: 11.87 | N32: 1 | O32: =PRODUCT(K32:N32) -> 11.87
A33: HAMBURGUESA CARNE | B33: 11900 | C33: 12450 | D33: 12450 | E33: 11900 | F33: =PRODUCT(E33,G2) -> 12495 | J33: Para chori | K33: 5.73 | N33: =(D31) -> 11850 | O33: =PRODUCT(K33:N33) -> 67900.5
A34: MILANESA CARNE | B34: 17200 | C34: 18000 | D34: 18500 | E34: 17200 | F34: =PRODUCT(E34,G2) -> 18060
A35: MOLIDA ESPECIAL | B35: 18900 | C35: 19850 | D35: 19850 | E35: 18900 | F35: =PRODUCT(E35,G2) -> 19845 | J35: Kg Rinde | K35: =SUM(K7:K34) -> 108.795 | N35: =(-O35*100)/O4 -> 20.819717 | O35: =SUM(O4:O34) -> 240342.82
A36: GRASA | B36: 990 | C36: 1100 | D36: 1400 | E36: 990 | F36: =PRODUCT(E36,G2) -> 1039.5
A38: GRANJA DON CHACHO | F38: INCREMENTO | G38: 1.05
A39: OFERTAS DE ASADO | B39: penultimo | C39: ultimo | D39: $ Actual | E39: Pegar $ Actual para calcular incremento | F39: Valor con calculo de incremento
A40: OFERTA 4KG 2+1+1 | B40: 38000 | C40: 39900 | D40: 41900 | E40: 39900 | F40: =PRODUCT(E40,G38) -> 41895
A41: OFERTA ASADO 3KG(2+1) | B41: 33600 | C41: 35300 | D41: 37300 | E41: 35300 | F41: =PRODUCT(E41,G38) -> 37065
...

Sheet PESAJES BALANCE 
B2: CHACHO 1 | J2: CHACHO 2 | R2: DON CHACHO 3 | Z2: CABAÑA DEL VALLE
B3: CORTES | C3: PESO | G3: PRECIO | H3: TOTAL | J3: CORTES | K3: PESO | O3: PRECIO | P3: TOTAL | R3: CORTES | S3: PESO | W3: PRECIO | X3: TOTAL | Z3: CORTES | AA3: PESO | AE3: PRECIO | AF3: TOTAL
B4: CARNE | H4: =SUM(H5:H41) -> #REF! | J4: CARNE | P4: =SUM(P5:P41) -> #REF! | R4: CARNE | X4: =SUM(X5:X41) -> #REF! | Z4: CARNE | AF4: =SUM(AF5:AF41) -> #REF!
B5: MEDIA RES DE CARNE | G5: =('DON CHACHO'!N4) -> 10400 | H5: =(G5*SUM(C5:F5)) -> 0 | J5: MEDIA RES DE CARNE | O5: =G5 -> 10400 | P5: =(O5*SUM(K5:N5)) -> 0 | R5: MEDIA RES DE CARNE | W5: =G5 -> 10400 | X5: =(W5*SUM(S5:V5)) -> 0 | Z5: MEDIA RES DE CARNE | AE5: =G5 -> 10400 | AF5: =(AE5*SUM(AA5:AD5)) -> 0
B6: OCTAVO | G6: =#REF! -> #REF! | H6: =(G6*SUM(C6:F6)) -> #REF! | J6: OCTAVO | O6: 4500 | P6: =(O6*SUM(K6:N6)) -> 0 | R6: OCTAVO | W6: =G6 -> #REF! | X6: =(W6*SUM(S6:V6)) -> #REF! | Z6: OCTAVO | AE6: =G6 -> #REF! | AF6: =(AE6*SUM(AA6:AD6)) -> #REF!
B7: COSTILLAR COMPLETO | G7: =(#REF!) -> #REF! | H7: =(G7*SUM(C7:F7)) -> #REF! | J7: COSTILLAR COMPLETO | O7: =G7 -> #REF! | P7: =(O7*SUM(K7:N7)) -> #REF! | R7: COSTILLAR COMPLETO | W7: =G7 -> #REF! | X7: =(W7*SUM(S7:V7)) -> #REF! | Z7: COSTILLAR COMPLETO | AE7: =G7 -> #REF! | AF7: =(AE7*SUM(AA7:AD7)) -> #REF!
B8: VACIO | G8: =('DON CHACHO'!D4) -> 22990 | H8: =(G8*SUM(C8:F8)) -> 0 | J8: VACIO | O8: =G8 -> 22990 | P8: =(O8*SUM(K8:N8)) -> 0 | R8: VACIO | W8: =G8 -> 22990 | X8: =(W8*SUM(S8:V8)) -> 0 | Z8: VACIO | AE8: =G8 -> 22990 | AF8: =(AE8*SUM(AA8:AD8)) -> 0
B9: QUEPERI | G9: =('DON CHACHO'!D5) -> 22950 | H9: =(G9*SUM(C9:F9)) -> 0 | J9: QUEPERI | O9: =G9 -> 22950 | P9: =(O9*SUM(K9:N9)) -> 0 | R9: QUEPERI | W9: =G9 -> 22950 | X9: =(W9*SUM(S9:V9)) -> 0 | Z9: QUEPERI | AE9: =G9 -> 22950 | AF9: =(AE9*SUM(AA9:AD9)) -> 0
B10: MATAMBRE | G10: =('DON CHACHO'!D51) -> 19900 | H10: =(G10*SUM(C10:F10)) -> 0 | J10: MATAMBRE | K10: 6.2 | O10: =G10 -> 19900 | P10: =(O10*SUM(K10:N10)) -> 123380 | R10: MATAMBRE | S10: 10.17 | T10: 3.31 | U10: 6 | W10: =G10 -> 19900 | X10: =(W10*SUM(S10:V10)) -> 387652 | Z10: MATAMBRE | AA10: 3 | AB10: 2.2 | AC10: 6.7 | AE10: =G10 -> 19900 | AF10: =(AE10*SUM(AA10:AD10)) -> 236810
B11: VUELITO | G11: =('DON CHACHO'!D7) -> 25950 | H11: =(G11*SUM(C11:F11)) -> 0 | J11: VUELITO | O11: =G11 -> 25950 | P11: =(O11*SUM(K11:N11)) -> 0 | R11: VUELITO | W11: =G11 -> 25950 | X11: =(W11*SUM(S11:V11)) -> 0 | Z11: VUELITO | AE11: =G11 -> 25950 | AF11: =(AE11*SUM(AA11:AD11)) -> 0
B12: COSTILLA ESPECIAL | G12: =('DON CHACHO'!D8) -> 19500 | H12: =(G12*SUM(C12:F12)) -> 0 | J12: COSTILLA ESPECIAL | K12: 4 | O12: =G12 -> 19500 | P12: =(O12*SUM(K12:N12)) -> 78000 | R12: COSTILLA ESPECIAL | W12: =G12 -> 19500 | X12: =(W12*SUM(S12:V12)) -> 0 | Z12: COSTILLA ESPECIAL | AA12: 17.6 | AB12: 3.9 | AE12: =G12 -> 19500 | AF12: =(AE12*SUM(AA12:AD12)) -> 419250
B13: TAPA DE NALGA | G13: =('DON CHACHO'!D9) -> 19180 | H13: =(G13*SUM(C13:F13)) -> 0 | J13: TAPA DE NALGA | O13: =G13 -> 19180 | P13: =(O13*SUM(K13:N13)) -> 0 | R13: TAPA DE NALGA | S13: 3 | W13: =G13 -> 19180 | X13: =(W13*SUM(S13:V13)) -> 57540 | Z13: TAPA DE NALGA | AA13: 22.5 | AB13: 2.3 | AE13: =G13 -> 19180 | AF13: =(AE13*SUM(AA13:AD13)) -> 475664
B14: TAPA DE ASADO | G14: =('DON CHACHO'!D10) -> 17590 | H14: =(G14*SUM(C14:F14)) -> 0 | J14: TAPA DE ASADO | O14: =G14 -> 17590 | P14: =(O14*SUM(K14:N14)) -> 0 | R14: TAPA DE ASADO | W14: =G14 -> 17590 | X14: =(W14*SUM(S14:V14)) -> 0 | Z14: TAPA DE ASADO | AE14: =G14 -> 17590 | AF14: =(AE14*SUM(AA14:AD14)) -> 0
B15: PIERNA | C15: 154.1 | G15: 7700 | H15: =(G15*SUM(C15:F15)) -> 1186570 | J15: PIERNA | K15: 183.8 | O15: =G15 -> 7700 | P15: =(O15*SUM(K15:N15)) -> 1415260 | R15: PIERNA | W15: =G15 -> 7700 | X15: =(W15*SUM(S15:V15)) -> 0 | Z15: PIERNA | AA15: 37.5 | AB15: 34 | AC15: 30.5 | AD15: 31 | AE15: =G15 -> 7700 | AF15: =(AE15*SUM(AA15:AD15)) -> 1024100
B16: FALDA DE ESPALDA | G16: =('DON CHACHO'!D11) -> 15900 | H16: =(G16*SUM(C16:F16)) -> 0 | J16: FALDA DE ESPALDA | O16: =G16 -> 15900 | P16: =(O16*SUM(K16:N16)) -> 0 | R16: FALDA DE ESPALDA | S16: 14.4 | W16: =G16 -> 15900 | X16: =(W16*SUM(S16:V16)) -> 228960 | Z16: FALDA DE ESPALDA | AE16: =G16 -> 15900 | AF16: =(AE16*SUM(AA16:AD16)) -> 0
B17: CORTE AMERICANO | G17: =('DON CHACHO'!D12) -> 19900 | H17: =(G17*SUM(C17:F17)) -> 0 | J17: CORTE AMERICANO | O17: =G17 -> 19900 | P17: =(O17*SUM(K17:N17)) -> 0 | R17: CORTE AMERICANO | W17: =G17 -> 19900 | X17: =(W17*SUM(S17:V17)) -> 0 | Z17: CORTE AMERICANO | AE17: =G17 -> 19900 | AF17: =(AE17*SUM(AA17:AD17)) -> 0
B18: COSTELETA | C18: 192 | D18: 11 | G18: =('DON CHACHO'!D13) -> 17900 | H18: =(G18*SUM(C18:F18)) -> 3633700 | J18: COSTELETA | K18: 23.7 | L18: 1.4 | O18: =G18 -> 17900 | P18: =(O18*SUM(K18:N18)) -> 449290 | R18: COSTELETA | S18: 5.7 | T18: 2.9 | W18: =G18 -> 17900 | X18: =(W18*SUM(S18:V18)) -> 153940 | Z18: COSTELETA | AA18: 15 | AB18: 38 | AC18: 2.7 | AE18: =G18 -> 17900 | AF18: =(AE18*SUM(AA18:AD18)) -> 997030
B19: FILET | C19: 18 | D19: 1 | G19: =('DON CHACHO'!D14) -> 23830 | H19: =(G19*SUM(C19:F19)) -> 452770 | J19: FILET | K19: 3.3 | O19: =G19 -> 23830 | P19: =(O19*SUM(K19:N19)) -> 78639 | R19: FILET | W19: =G19 -> 23830 | X19: =(W19*SUM(S19:V19)) -> 0 | Z19: FILET | AA19: 1 | AE19: =G19 -> 23830 | AF19: =(AE19*SUM(AA19:AD19)) -> 23830
B20: LOMO | G20: =('DON CHACHO'!D15) -> 24850 | H20: =(G20*SUM(C20:F20)) -> 0 | J20: LOMO | K20: 2.8 | O20: =G20 -> 24850 | P20: =(O20*SUM(K20:N20)) -> 69580 | R20: LOMO | W20: =G20 -> 24850 | X20: =(W20*SUM(S20:V20)) -> 0 | Z20: LOMO | AE20: =G20 -> 24850 | AF20: =(AE20*SUM(AA20:AD20)) -> 0
B21: PULPA | C21: 25 | G21: =('DON CHACHO'!D16) -> 24850 | H21: =(G21*SUM(C21:F21)) -> 621250 | J21: PULPA | K21: 12.2 | O21: =G21 -> 24850 | P21: =(O21*SUM(K21:N21)) -> 303170 | R21: PULPA | S21: 4.8 | W21: =G21 -> 24850 | X21: =(W21*SUM(S21:V21)) -> 119280 | Z21: PULPA | AA21: 6 | AB21: 8.9 | AE21: =G21 -> 24850 | AF21: =(AE21*SUM(AA21:AD21)) -> 370265
B22: PICANA | C22: 15 | D22: 1.1 | G22: =('DON CHACHO'!D17) -> 20850 | H22: =(G22*SUM(C22:F22)) -> 335685 | J22: PICANA | K22: 3.6 | O22: =G22 -> 20850 | P22: =(O22*SUM(K22:N22)) -> 75060 | R22: PICANA | S22: 1.38 | T22: 2.94 | W22: =G22 -> 20850 | X22: =(W22*SUM(S22:V22)) -> 90072 | Z22: PICANA | AA22: 3.5 | AB22: 7.8 | AE22: =G22 -> 20850 | AF22: =(AE22*SUM(AA22:AD22)) -> 235605
B23: PECETO | C23: 6.5 | G23: =('DON CHACHO'!D18) -> 22190 | H23: =(G23*SUM(C23:F23)) -> 144235 | J23: PECETO | K23: 7 | O23: =G23 -> 22190 | P23: =(O23*SUM(K23:N23)) -> 155330 | R23: PECETO | S23: 2.44 | W23: =G23 -> 22190 | X23: =(W23*SUM(S23:V23)) -> 54143.6 | Z23: PECETO | AA23: 3 | AB23: 1.6 | AE23: =G23 -> 22190 | AF23: =(AE23*SUM(AA23:AD23)) -> 102074
B24: BOLA DE LOMO | G24: =('DON CHACHO'!D19) -> 19750 | H24: =(G24*SUM(C24:F24)) -> 0 | J24: BOLA DE LOMO | K24: 1.3 | O24: =G24 -> 19750 | P24: =(O24*SUM(K24:N24)) -> 25675 | R24: BOLA DE LOMO | S24: 5.66 | W24: =G24 -> 19750 | X24: =(W24*SUM(S24:V24)) -> 111785 | Z24: BOLA DE LOMO | AA24: 1.3 | AE24: =G24 -> 19750 | AF24: =(AE24*SUM(AA24:AD24)) -> 25675
B25: CUADRADA | C25: 12 | G25: =('DON CHACHO'!D20) -> 19750 | H25: =(G25*SUM(C25:F25)) -> 237000 | J25: CUADRADA | O25: =G25 -> 19750 | P25: =(O25*SUM(K25:N25)) -> 0 | R25: CUADRADA | S25: 6.2 | W25: =G25 -> 19750 | X25: =(W25*SUM(S25:V25)) -> 122450 | Z25: CUADRADA | AE25: =G25 -> 19750 | AF25: =(AE25*SUM(AA25:AD25)) -> 0
B26: PALETA | G26: =('DON CHACHO'!D21) -> 18950 | H26: =(G26*SUM(C26:F26)) -> 0 | J26: PALETA | O26: =G26 -> 18950 | P26: =(O26*SUM(K26:N26)) -> 0 | R26: PALETA | W26: =G26 -> 18950 | X26: =(W26*SUM(S26:V26)) -> 0 | Z26: PALETA | AA26: 10 | AE26: =G26 -> 18950 | AF26: =(AE26*SUM(AA26:AD26)) -> 189500
B27: SOBACO | G27: =('DON CHACHO'!D22) -> 15380 | H27: =(G27*SUM(C27:F27)) -> 0 | J27: SOBACO | O27: =G27 -> 15380 | P27: =(O27*SUM(K27:N27)) -> 0 | R27: SOBACO | S27: 1.4 | W27: =G27 -> 15380 | X27: =(W27*SUM(S27:V27)) -> 21532 | Z27: SOBACO | AE27: =G27 -> 15380 | AF27: =(AE27*SUM(AA27:AD27)) -> 0
B28: TORTUGA | G28: =('DON CHACHO'!D23) -> 15380 | H28: =(G28*SUM(C28:F28)) -> 0 | J28: TORTUGA | K28: 2 | O28: =G28 -> 15380 | P28: =(O28*SUM(K28:N28)) -> 30760 | R28: TORTUGA | W28: =G28 -> 15380 | X28: =(W28*SUM(S28:V28)) -> 0 | Z28: TORTUGA | AE28: =G28 -> 15380 | AF28: =(AE28*SUM(AA28:AD28)) -> 0
B29: MOLIDA COMUN | G29: =('DON CHACHO'!D24) -> 11950 | H29: =(G29*SUM(C29:F29)) -> 0 | J29: MOLIDA COMUN | O29: =G29 -> 11950 | P29: =(O29*SUM(K29:N29)) -> 0 | R29: MOLIDA COMUN | S29: 7.9 | T29: 7 | U29: 2.6 | V29: 1.2 | W29: =G29 -> 11950 | X29: =(W29*SUM(S29:V29)) -> 223465 | Z29: MOLIDA COMUN | AE29: =G29 -> 11950 | AF29: =(AE29*SUM(AA29:AD29)) -> 0
B30: PUCHERO ESPECIAL | G30: =('DON CHACHO'!D25) -> 10400 | H30: =(G30*SUM(C30:F30)) -> 0 | J30: PUCHERO ESPECIAL | K30: 1.8 | O30: =G30 -> 10400 | P30: =(O30*SUM(K30:N30)) -> 18720 | R30: PUCHERO ESPECIAL | S30: 5.4 | T30: 8.8 | W30: =G30 -> 10400 | X30: =(W30*SUM(S30:V30)) -> 147680 | Z30: PUCHERO ESPECIAL | AA30: 2.5 | AE30: =G30 -> 10400 | AF30: =(AE30*SUM(AA30:AD30)) -> 26000
B31: PUCHERO PALETA | G31: =('DON CHACHO'!D26) -> 10400 | H31: =(G31*SUM(C31:F31)) -> 0 | J31: PUCHERO PALETA | O31: =G31 -> 10400 | P31: =(O31*SUM(K31:N31)) -> 0 | R31: PUCHERO PALETA | W31: =G31 -> 10400 | X31: =(W31*SUM(S31:V31)) -> 0 | Z31: PUCHERO PALETA | AE31: =G31 -> 10400 | AF31: =(AE31*SUM(AA31:AD31)) -> 0
B32: PUCHERO COGOTE | C32: 1.5 | G32: =('DON CHACHO'!D27) -> 9975 | H32: =(G32*SUM(C32:F32)) -> 14962.5 | J32: PUCHERO COGOTE | O32: =G32 -> 9975 | P32: =(O32*SUM(K32:N32)) -> 0 | R32: PUCHERO COGOTE | W32: =G32 -> 9975 | X32: =(W32*SUM(S32:V32)) -> 0 | Z32: PUCHERO COGOTE | AE32: =G32 -> 9975 | AF32: =(AE32*SUM(AA32:AD32)) -> 0
B33: PUCHERO COMUN | C33: 6.4 | G33: =('DON CHACHO'!D28) -> 3000 | H33: =(G33*SUM(C33:F33)) -> 19200 | J33: PUCHERO COMUN | O33: =G33 -> 3000 | P33: =(O33*SUM(K33:N33)) -> 0 | R33: PUCHERO COMUN | S33: 15.4 | T33: 2.6 | U33: 3.5 | W33: =G33 -> 3000 | X33: =(W33*SUM(S33:V33)) -> 64500 | Z33: PUCHERO COMUN | AA33: 2.3 | AE33: =G33 -> 3000 | AF33: =(AE33*SUM(AA33:AD33)) -> 6900
B34: PUCHERO COMUN 3KG | G34: =('DON CHACHO'!D29) -> 7500 | H34: =(G34*SUM(C34:F34)) -> 0 | J34: PUCHERO COMUN 3KG | O34: =G34 -> 7500 | P34: =(O34*SUM(K34:N34)) -> 0 | R34: PUCHERO COMUN 3KG | W34: =G34 -> 7500 | X34: =(W34*SUM(S34:V34)) -> 0 | Z34: PUCHERO COMUN 3KG | AE34: =G34 -> 7500 | AF34: =(AE34*SUM(AA34:AD34)) -> 0
B35: BUTIFARRA | C35: 25 | G35: =('DON CHACHO'!D30) -> 12490 | H35: =(G35*SUM(C35:F35)) -> 312250 | J35: BUTIFARRA | O35: =G35 -> 12490 | P35: =(O35*SUM(K35:N35)) -> 0 | R35: BUTIFARRA | S35: 2.8 | W35: =G35 -> 12490 | X35: =(W35*SUM(S35:V35)) -> 34972 | Z35: BUTIFARRA | AA35: 8 | AB35: 3 | AE35: =G35 -> 12490 | AF35: =(AE35*SUM(AA35:AD35)) -> 137390
B36: CHORIZO CRIOLLO | C36: 90 | D36: 15 | E36: 5 | G36: =('DON CHACHO'!D31) -> 11850 | H36: =(G36*SUM(C36:F36)) -> 1303500 | J36: CHORIZO CRIOLLO | K36: 14.4 | L36: 30 | O36: =G36 -> 11850 | P36: =(O36*SUM(K36:N36)) -> 526140 | R36: CHORIZO CRIOLLO | S36: 51.5 | T36: 9.1 | U36: 2.55 | W36: =G36 -> 11850 | X36: =(W36*SUM(S36:V36)) -> 748327.5 | Z36: CHORIZO CRIOLLO | AA36: 35 | AB36: 1.2 | AC36: 0.4 | AE36: =G36 -> 11850 | AF36: =(AE36*SUM(AA36:AD36)) -> 433710
B37: CHORIZO DE CERDO | C37: 27 | D37: 4 | G37: =('DON CHACHO'!D32) -> 11950 | H37: =(G37*SUM(C37:F37)) -> 370450 | J37: CHORIZO DE CERDO | K37: 6.9 | O37: =G37 -> 11950 | P37: =(O37*SUM(K37:N37)) -> 82455 | R37: CHORIZO DE CERDO | S37: 5.3 | T37: 1.6 | W37: =G37 -> 11950 | X37: =(W37*SUM(S37:V37)) -> 82455 | Z37: CHORIZO DE CERDO | AA37: 23 | AB37: 1.5 | AE37: =G37 -> 11950 | AF37: =(AE37*SUM(AA37:AD37)) -> 292775
B38: HAMBURGUESA CARNE | C38: 10 | G38: =('DON CHACHO'!D33) -> 12450 | H38: =(G38*SUM(C38:F38)) -> 124500 | J38: HAMBURGUESA CARNE | K38: 35 | O38: =G38 -> 12450 | P38: =(O38*SUM(K38:N38)) -> 435750 | R38: HAMBURGUESA CARNE | S38: 29.3 | W38: =G38 -> 12450 | X38: =(W38*SUM(S38:V38)) -> 364785 | Z38: HAMBURGUESA CARNE | AE38: =G38 -> 12450 | AF38: =(AE38*SUM(AA38:AD38)) -> 0
B39: MILANESA CARNE | G39: =('DON CHACHO'!D34) -> 18500 | H39: =(G39*SUM(C39:F39)) -> 0 | J39: MILANESA CARNE | O39: =G39 -> 18500 | P39: =(O39*SUM(K39:N39)) -> 0 | R39: MILANESA CARNE | S39: 2.8 | W39: =G39 -> 18500 | X39: =(W39*SUM(S39:V39)) -> 51800 | Z39: MILANESA CARNE | AA39: 6 | AE39: =G39 -> 18500 | AF39: =(AE39*SUM(AA39:AD39)) -> 111000
B40: MOLIDA ESPECIAL | G40: =('DON CHACHO'!D35) -> 19850 | H40: =(G40*SUM(C40:F40)) -> 0 | J40: MOLIDA ESPECIAL | O40: =G40 -> 19850 | P40: =(O40*SUM(K40:N40)) -> 0 | R40: MOLIDA ESPECIAL | W40: =G40 -> 19850 | X40: =(W40*SUM(S40:V40)) -> 0 | Z40: MOLIDA ESPECIAL | AE40: =G40 -> 19850 | AF40: =(AE40*SUM(AA40:AD40)) -> 0
B41: GRASA | G41: =('DON CHACHO'!D36) -> 1400 | H41: =(G41*SUM(C41:F41)) -> 0 | J41: GRASA | O41: =G41 -> 1400 | P41: =(O41*SUM(K41:N41)) -> 0 | R41: GRASA | W41: =G41 -> 1400 | X41: =(W41*SUM(S41:V41)) -> 0 | Z41: GRASA | AE41: =G41 -> 1400 | AF41: =(AE41*SUM(AA41:AD41)) -> 0
...
